Workbook

Sheet README
A1: Kuja Grant — Test Cases v5.0
A2: 306 test cases across 32 modules
A4: HOW TO USE THIS WORKBOOK
A6: 1. One sheet per module/category (see tabs at the bottom).
A7: 2. Pick a sheet, work through test cases row by row.
A8: 3. On each row, fill in:
A9: • Status: pick from dropdown (PASS / FAIL / BLOCKED / N/A / IN PROGRESS)
A10: • Tester: your name or initials
A11: • Run Date: when you executed the test
A12: • Comments / Defect ID: notes, screenshots, JIRA/issue link
A14: 4. The Summary sheet auto-rolls up PASS/FAIL counts via live formulas.
A15: 5. Status cells are colour-coded automatically:
... A36: Generated against commit at build time.

Sheet Summary
A1: Module | B1: Tab Link | C1: Total | D1: P1 | E1: P2 | F1: P3 | G1: PASS | H1: FAIL | I1: BLOCKED | J1: Pending | K1: Pass Rate
A2: Authentication | B2: Open › | C2: 15 | D2: 8 | E2: 6 | F2: 1 | G2: =COUNTIF('Authentication'!J2:J16,"PASS") | H2: =COUNTIF('Authentication'!J2:J16,"FAIL") | I2: =COUNTIF('Authentication'!J2:J16,"BLOCKED") | J2: =15-COUNTIF('Authentication'!J2:J16,"PASS")-COUNTIF('Authentication'!J2:J16,"FAIL")-COUNTIF('Authentication'!J2:J16,"BLOCKED")-COUNTIF('Authentication'!J2:J16,"N/A") | K2: =IFERROR(COUNTIF('Authentication'!J2:J16,"PASS")/(COUNTIF('Authentication'!J2:J16,"PASS")+COUNTIF('Authentication'!J2:J16,"FAIL")),"")
A3: Dashboard | B3: Open › | C3: 9 | D3: 4 | E3: 3 | F3: 2 | G3: =COUNTIF('Dashboard'!J2:J10,"PASS") | H3: =COUNTIF('Dashboard'!J2:J10,"FAIL") | I3: =COUNTIF('Dashboard'!J2:J10,"BLOCKED") | J3: =9-COUNTIF('Dashboard'!J2:J10,"PASS")-COUNTIF('Dashboard'!J2:J10,"FAIL")-COUNTIF('Dashboard'!J2:J10,"BLOCKED")-COUNTIF('Dashboard'!J2:J10,"N/A") | K3: =IFERROR(COUNTIF('Dashboard'!J2:J10,"PASS")/(COUNTIF('Dashboard'!J2:J10,"PASS")+COUNTIF('Dashboard'!J2:J10,"FAIL")),"")
A4: Grants | B4: Open › | C4: 16 | D4: 10 | E4: 6 | F4: 0 | G4: =COUNTIF('Grants'!J2:J17,"PASS") | H4: =COUNTIF('Grants'!J2:J17,"FAIL") | I4: =COUNTIF('Grants'!J2:J17,"BLOCKED") | J4: =16-COUNTIF('Grants'!J2:J17,"PASS")-COUNTIF('Grants'!J2:J17,"FAIL")-COUNTIF('Grants'!J2:J17,"BLOCKED")-COUNTIF('Grants'!J2:J17,"N/A") | K4: =IFERROR(COUNTIF('Grants'!J2:J17,"PASS")/(COUNTIF('Grants'!J2:J17,"PASS")+COUNTIF('Grants'!J2:J17,"FAIL")),"")
A5: Applications | B5: Open › | C5: 22 | D5: 17 | E5: 5 | F5: 0 | G5: =COUNTIF('Applications'!J2:J23,"PASS") | H5: =COUNTIF('Applications'!J2:J23,"FAIL") | I5: =COUNTIF('Applications'!J2:J23,"BLOCKED") | J5: =22-COUNTIF('Applications'!J2:J23,"PASS")-COUNTIF('Applications'!J2:J23,"FAIL")-COUNTIF('Applications'!J2:J23,"BLOCKED")-COUNTIF('Applications'!J2:J23,"N/A") | K5: =IFERROR(COUNTIF('Applications'!J2:J23,"PASS")/(COUNTIF('Applications'!J2:J23,"PASS")+COUNTIF('Applications'!J2:J23,"FAIL")),"")
A6: Assessments | B6: Open › | C6: 11 | D6: 5 | E6: 6 | F6: 0 | G6: =COUNTIF('Assessments'!J2:J12,"PASS") | H6: =COUNTIF('Assessments'!J2:J12,"FAIL") | I6: =COUNTIF('Assessments'!J2:J12,"BLOCKED") | J6: =11-COUNTIF('Assessments'!J2:J12,"PASS")-COUNTIF('Assessments'!J2:J12,"FAIL")-COUNTIF('Assessments'!J2:J12,"BLOCKED")-COUNTIF('Assessments'!J2:J12,"N/A") | K6: =IFERROR(COUNTIF('Assessments'!J2:J12,"PASS")/(COUNTIF('Assessments'!J2:J12,"PASS")+COUNTIF('Assessments'!J2:J12,"FAIL")),"")
A7: AI Services | B7: Open › | C7: 11 | D7: 5 | E7: 6 | F7: 0 | G7: =COUNTIF('AI Services'!J2:J12,"PASS") | H7: =COUNTIF('AI Services'!J2:J12,"FAIL") | I7: =COUNTIF('AI Services'!J2:J12,"BLOCKED") | J7: =11-COUNTIF('AI Services'!J2:J12,"PASS")-COUNTIF('AI Services'!J2:J12,"FAIL")-COUNTIF('AI Services'!J2:J12,"BLOCKED")-COUNTIF('AI Services'!J2:J12,"N/A") | K7: =IFERROR(COUNTIF('AI Services'!J2:J12,"PASS")/(COUNTIF('AI Services'!J2:J12,"PASS")+COUNTIF('AI Services'!J2:J12,"FAIL")),"")
A8: Compliance & Sanctions | B8: Open › | C8: 7 | D8: 3 | E8: 4 | F8: 0 | G8: =COUNTIF('Compliance & Sanctions'!J2:J8,"PASS") | H8: =COUNTIF('Compliance & Sanctions'!J2:J8,"FAIL") | I8: =COUNTIF('Compliance & Sanctions'!J2:J8,"BLOCKED") | J8: =7-COUNTIF('Compliance & Sanctions'!J2:J8,"PASS")-COUNTIF('Compliance & Sanctions'!J2:J8,"FAIL")-COUNTIF('Compliance & Sanctions'!J2:J8,"BLOCKED")-COUNTIF('Compliance & Sanctions'!J2:J8,"N/A") | K8: =IFERROR(COUNTIF('Compliance & Sanctions'!J2:J8,"PASS")/(COUNTIF('Compliance & Sanctions'!J2:J8,"PASS")+COUNTIF('Compliance & Sanctions'!J2:J8,"FAIL")),"")
A9: Registry Verification | B9: Open › | C9: 7 | D9: 2 | E9: 5 | F9: 0 | G9: =COUNTIF('Registry Verification'!J2:J8,"PASS") | H9: =COUNTIF('Registry Verification'!J2:J8,"FAIL") | I9: =COUNTIF('Registry Verification'!J2:J8,"BLOCKED") | J9: =7-COUNTIF('Registry Verification'!J2:J8,"PASS")-COUNTIF('Registry Verification'!J2:J8,"FAIL")-COUNTIF('Registry Verification'!J2:J8,"BLOCKED")-COUNTIF('Registry Verification'!J2:J8,"N/A") | K9: =IFERROR(COUNTIF('Registry Verification'!J2:J8,"PASS")/(COUNTIF('Registry Verification'!J2:J8,"PASS")+COUNTIF('Registry Verification'!J2:J8,"FAIL")),"")
A10: Reports | B10: Open › | C10: 10 | D10: 8 | E10: 2 | F10: 0 | G10: =COUNTIF('Reports'!J2:J11,"PASS") | H10: =COUNTIF('Reports'!J2:J11,"FAIL") | I10: =COUNTIF('Reports'!J2:J11,"BLOCKED") | J10: =10-COUNTIF('Reports'!J2:J11,"PASS")-COUNTIF('Reports'!J2:J11,"FAIL")-COUNTIF('Reports'!J2:J11,"BLOCKED")-COUNTIF('Reports'!J2:J11,"N/A") | K10: =IFERROR(COUNTIF('Reports'!J2:J11,"PASS")/(COUNTIF('Reports'!J2:J11,"PASS")+COUNTIF('Reports'!J2:J11,"FAIL")),"")
A11: Internationalization | B11: Open › | C11: 8 | D11: 1 | E11: 7 | F11: 0 | G11: =COUNTIF('Internationalization'!J2:J9,"PASS") | H11: =COUNTIF('Internationalization'!J2:J9,"FAIL") | I11: =COUNTIF('Internationalization'!J2:J9,"BLOCKED") | J11: =8-COUNTIF('Internationalization'!J2:J9,"PASS")-COUNTIF('Internationalization'!J2:J9,"FAIL")-COUNTIF('Internationalization'!J2:J9,"BLOCKED")-COUNTIF('Internationalization'!J2:J9,"N/A") | K11: =IFERROR(COUNTIF('Internationalization'!J2:J9,"PASS")/(COUNTIF('Internationalization'!J2:J9,"PASS")+COUNTIF('Internationalization'!J2:J9,"FAIL")),"")
A12: Access Control | B12: Open › | C12: 6 | D12: 6 | E12: 0 | F12: 0 | G12: =COUNTIF('Access Control'!J2:J7,"PASS") | H12: =COUNTIF('Access Control'!J2:J7,"FAIL") | I12: =COUNTIF('Access Control'!J2:J7,"BLOCKED") | J12: =6-COUNTIF('Access Control'!J2:J7,"PASS")-COUNTIF('Access Control'!J2:J7,"FAIL")-COUNTIF('Access Control'!J2:J7,"BLOCKED")-COUNTIF('Access Control'!J2:J7,"N/A") | K12: =IFERROR(COUNTIF('Access Control'!J2:J7,"PASS")/(COUNTIF('Access Control'!J2:J7,"PASS")+COUNTIF('Access Control'!J2:J7,"FAIL")),"")
A13: System Health | B13: Open › | C13: 6 | D13: 2 | E13: 3 | F13: 1 | G13: =COUNTIF('System Health'!J2:J7,"PASS") | H13: =COUNTIF('System Health'!J2:J7,"FAIL") | I13: =COUNTIF('System Health'!J2:J7,"BLOCKED") | J13: =6-COUNTIF('System Health'!J2:J7,"PASS")-COUNTIF('System Health'!J2:J7,"FAIL")-COUNTIF('System Health'!J2:J7,"BLOCKED")-COUNTIF('System Health'!J2:J7,"N/A") | K13: =IFERROR(COUNTIF('System Health'!J2:J7,"PASS")/(COUNTIF('System Health'!J2:J7,"PASS")+COUNTIF('System Health'!J2:J7,"FAIL")),"")
A14: Documents | B14: Open › | C14: 6 | D14: 4 | E14: 2 | F14: 0 | G14: =COUNTIF('Documents'!J2:J7,"PASS") | H14: =COUNTIF('Documents'!J2:J7,"FAIL") | I14: =COUNTIF('Documents'!J2:J7,"BLOCKED") | J14: =6-COUNTIF('Documents'!J2:J7,"PASS")-COUNTIF('Documents'!J2:J7,"FAIL")-COUNTIF('Documents'!J2:J7,"BLOCKED")-COUNTIF('Documents'!J2:J7,"N/A") | K14: =IFERROR(COUNTIF('Documents'!J2:J7,"PASS")/(COUNTIF('Documents'!J2:J7,"PASS")+COUNTIF('Documents'!J2:J7,"FAIL")),"")
A15: Organization Profile | B15: Open › | C15: 3 | D15: 0 | E15: 2 | F15: 1 | G15: =COUNTIF('Organization Profile'!J2:J4,"PASS") | H15: =COUNTIF('Organization Profile'!J2:J4,"FAIL") | I15: =COUNTIF('Organization Profile'!J2:J4,"BLOCKED") | J15: =3-COUNTIF('Organization Profile'!J2:J4,"PASS")-COUNTIF('Organization Profile'!J2:J4,"FAIL")-COUNTIF('Organization Profile'!J2:J4,"BLOCKED")-COUNTIF('Organization Profile'!J2:J4,"N/A") | K15: =IFERROR(COUNTIF('Organization Profile'!J2:J4,"PASS")/(COUNTIF('Organization Profile'!J2:J4,"PASS")+COUNTIF('Organization Profile'!J2:J4,"FAIL")),"")
A16: End-to-End Workflows | B16: Open › | C16: 4 | D16: 2 | E16: 2 | F16: 0 | G16: =COUNTIF('End-to-End Workflows'!J2:J5,"PASS") | H16: =COUNTIF('End-to-End Workflows'!J2:J5,"FAIL") | I16: =COUNTIF('End-to-End Workflows'!J2:J5,"BLOCKED") | J16: =4-COUNTIF('End-to-End Workflows'!J2:J5,"PASS")-COUNTIF('End-to-End Workflows'!J2:J5,"FAIL")-COUNTIF('End-to-End Workflows'!J2:J5,"BLOCKED")-COUNTIF('End-to-End Workflows'!J2:J5,"N/A") | K16: =IFERROR(COUNTIF('End-to-End Workflows'!J2:J5,"PASS")/(COUNTIF('End-to-End Workflows'!J2:J5,"PASS")+COUNTIF('End-to-End Workflows'!J2:J5,"FAIL")),"")
A17: AI Chat | B17: Open › | C17: 7 | D17: 5 | E17: 2 | F17: 0 | G17: =COUNTIF('AI Chat'!J2:J8,"PASS") | H17: =COUNTIF('AI Chat'!J2:J8,"FAIL") | I17: =COUNTIF('AI Chat'!J2:J8,"BLOCKED") | J17: =7-COUNTIF('AI Chat'!J2:J8,"PASS")-COUNTIF('AI Chat'!J2:J8,"FAIL")-COUNTIF('AI Chat'!J2:J8,"BLOCKED")-COUNTIF('AI Chat'!J2:J8,"N/A") | K17: =IFERROR(COUNTIF('AI Chat'!J2:J8,"PASS")/(COUNTIF('AI Chat'!J2:J8,"PASS")+COUNTIF('AI Chat'!J2:J8,"FAIL")),"")
A18: Reviewer Assignment | B18: Open › | C18: 5 | D18: 1 | E18: 4 | F18: 0 | G18: =COUNTIF('Reviewer Assignment'!J2:J6,"PASS") | H18: =COUNTIF('Reviewer Assignment'!J2:J6,"FAIL") | I18: =COUNTIF('Reviewer Assignment'!J2:J6,"BLOCKED") | J18: =5-COUNTIF('Reviewer Assignment'!J2:J6,"PASS")-COUNTIF('Reviewer Assignment'!J2:J6,"FAIL")-COUNTIF('Reviewer Assignment'!J2:J6,"BLOCKED")-COUNTIF('Reviewer Assignment'!J2:J6,"N/A") | K18: =IFERROR(COUNTIF('Reviewer Assignment'!J2:J6,"PASS")/(COUNTIF('Reviewer Assignment'!J2:J6,"PASS")+COUNTIF('Reviewer Assignment'!J2:J6,"FAIL")),"")
A19: Donor Intelligence | B19: Open › | C19: 6 | D19: 1 | E19: 5 | F19: 0 | G19: =COUNTIF('Donor Intelligence'!J2:J7,"PASS") | H19: =COUNTIF('Donor Intelligence'!J2:J7,"FAIL") | I19: =COUNTIF('Donor Intelligence'!J2:J7,"BLOCKED") | J19: =6-COUNTIF('Donor Intelligence'!J2:J7,"PASS")-COUNTIF('Donor Intelligence'!J2:J7,"FAIL")-COUNTIF('Donor Intelligence'!J2:J7,"BLOCKED")-COUNTIF('Donor Intelligence'!J2:J7,"N/A") | K19: =IFERROR(COUNTIF('Donor Intelligence'!J2:J7,"PASS")/(COUNTIF('Donor Intelligence'!J2:J7,"PASS")+COUNTIF('Donor Intelligence'!J2:J7,"FAIL")),"")
A20: PWA + Security | B20: Open › | C20: 7 | D20: 0 | E20: 2 | F20: 5 | G20: =COUNTIF('PWA + Security'!J2:J8,"PASS") | H20: =COUNTIF('PWA + Security'!J2:J8,"FAIL") | I20: =COUNTIF('PWA + Security'!J2:J8,"BLOCKED") | J20: =7-COUNTIF('PWA + Security'!J2:J8,"PASS")-COUNTIF('PWA + Security'!J2:J8,"FAIL")-COUNTIF('PWA + Security'!J2:J8,"BLOCKED")-COUNTIF('PWA + Security'!J2:J8,"N/A") | K20: =IFERROR(COUNTIF('PWA + Security'!J2:J8,"PASS")/(COUNTIF('PWA + Security'!J2:J8,"PASS")+COUNTIF('PWA + Security'!J2:J8,"FAIL")),"")
A21: Metrics + Feedback | B21: Open › | C21: 7 | D21: 3 | E21: 2 | F21: 2 | G21: =COUNTIF('Metrics + Feedback'!J2:J8,"PASS") | H21: =COUNTIF('Metrics + Feedback'!J2:J8,"FAIL") | I21: =COUNTIF('Metrics + Feedback'!J2:J8,"BLOCKED") | J21: =7-COUNTIF('Metrics + Feedback'!J2:J8,"PASS")-COUNTIF('Metrics + Feedback'!J2:J8,"FAIL")-COUNTIF('Metrics + Feedback'!J2:J8,"BLOCKED")-COUNTIF('Metrics + Feedback'!J2:J8,"N/A") | K21: =IFERROR(COUNTIF('Metrics + Feedback'!J2:J8,"PASS")/(COUNTIF('Metrics + Feedback'!J2:J8,"PASS")+COUNTIF('Metrics + Feedback'!J2:J8,"FAIL")),"")
A22: API Wiring | B22: Open › | C22: 5 | D22: 2 | E22: 3 | F22: 0 | G22: =COUNTIF('API Wiring'!J2:J6,"PASS") | H22: =COUNTIF('API Wiring'!J2:J6,"FAIL") | I22: =COUNTIF('API Wiring'!J2:J6,"BLOCKED") | J22: =5-COUNTIF('API Wiring'!J2:J6,"PASS")-COUNTIF('API Wiring'!J2:J6,"FAIL")-COUNTIF('API Wiring'!J2:J6,"BLOCKED")-COUNTIF('API Wiring'!J2:J6,"N/A") | K22: =IFERROR(COUNTIF('API Wiring'!J2:J6,"PASS")/(COUNTIF('API Wiring'!J2:J6,"PASS")+COUNTIF('API Wiring'!J2:J6,"FAIL")),"")
A23: AI Chat Edge | B23: Open › | C23: 15 | D23: 2 | E23: 7 | F23: 6 | G23: =COUNTIF('AI Chat Edge'!J2:J16,"PASS") | H23: =COUNTIF('AI Chat Edge'!J2:J16,"FAIL") | I23: =COUNTIF('AI Chat Edge'!J2:J16,"BLOCKED") | J23: =15-COUNTIF('AI Chat Edge'!J2:J16,"PASS")-COUNTIF('AI Chat Edge'!J2:J16,"FAIL")-COUNTIF('AI Chat Edge'!J2:J16,"BLOCKED")-COUNTIF('AI Chat Edge'!J2:J16,"N/A") | K23: =IFERROR(COUNTIF('AI Chat Edge'!J2:J16,"PASS")/(COUNTIF('AI Chat Edge'!J2:J16,"PASS")+COUNTIF('AI Chat Edge'!J2:J16,"FAIL")),"")
A24: Reviewer Auto Edge | B24: Open › | C24: 12 | D24: 3 | E24: 6 | F24: 3 | G24: =COUNTIF('Reviewer Auto Edge'!J2:J13,"PASS") | H24: =COUNTIF('Reviewer Auto Edge'!J2:J13,"FAIL") | I24: =COUNTIF('Reviewer Auto Edge'!J2:J13,"BLOCKED") | J24: =12-COUNTIF('Reviewer Auto Edge'!J2:J13,"PASS")-COUNTIF('Reviewer Auto Edge'!J2:J13,"FAIL")-COUNTIF('Reviewer Auto Edge'!J2:J13,"BLOCKED")-COUNTIF('Reviewer Auto Edge'!J2:J13,"N/A") | K24: =IFERROR(COUNTIF('Reviewer Auto Edge'!J2:J13,"PASS")/(COUNTIF('Reviewer Auto Edge'!J2:J13,"PASS")+COUNTIF('Reviewer Auto Edge'!J2:J13,"FAIL")),"")
A25: Donor Intel Edge | B25: Open › | C25: 12 | D25: 4 | E25: 5 | F25: 3 | G25: =COUNTIF('Donor Intel Edge'!J2:J13,"PASS") | H25: =COUNTIF('Donor Intel Edge'!J2:J13,"FAIL") | I25: =COUNTIF('Donor Intel Edge'!J2:J13,"BLOCKED") | J25: =12-COUNTIF('Donor Intel Edge'!J2:J13,"PASS")-COUNTIF('Donor Intel Edge'!J2:J13,"FAIL")-COUNTIF('Donor Intel Edge'!J2:J13,"BLOCKED")-COUNTIF('Donor Intel Edge'!J2:J13,"N/A") | K25: =IFERROR(COUNTIF('Donor Intel Edge'!J2:J13,"PASS")/(COUNTIF('Donor Intel Edge'!J2:J13,"PASS")+COUNTIF('Donor Intel Edge'!J2:J13,"FAIL")),"")
A26: PWA Negatives | B26: Open › | C26: 6 | D26: 0 | E26: 1 | F26: 5 | G26: =COUNTIF('PWA Negatives'!J2:J7,"PASS") | H26: =COUNTIF('PWA Negatives'!J2:J7,"FAIL") | I26: =COUNTIF('PWA Negatives'!J2:J7,"BLOCKED") | J26: =6-COUNTIF('PWA Negatives'!J2:J7,"PASS")-COUNTIF('PWA Negatives'!J2:J7,"FAIL")-COUNTIF('PWA Negatives'!J2:J7,"BLOCKED")-COUNTIF('PWA Negatives'!J2:J7,"N/A") | K26: =IFERROR(COUNTIF('PWA Negatives'!J2:J7,"PASS")/(COUNTIF('PWA Negatives'!J2:J7,"PASS")+COUNTIF('PWA Negatives'!J2:J7,"FAIL")),"")
A27: WebAuthn Negatives | B27: Open › | C27: 9 | D27: 3 | E27: 5 | F27: 1 | G27: =COUNTIF('WebAuthn Negatives'!J2:J10,"PASS") | H27: =COUNTIF('WebAuthn Negatives'!J2:J10,"FAIL") | I27: =COUNTIF('WebAuthn Negatives'!J2:J10,"BLOCKED") | J27: =9-COUNTIF('WebAuthn Negatives'!J2:J10,"PASS")-COUNTIF('WebAuthn Negatives'!J2:J10,"FAIL")-COUNTIF('WebAuthn Negatives'!J2:J10,"BLOCKED")-COUNTIF('WebAuthn Negatives'!J2:J10,"N/A") | K27: =IFERROR(COUNTIF('WebAuthn Negatives'!J2:J10,"PASS")/(COUNTIF('WebAuthn Negatives'!J2:J10,"PASS")+COUNTIF('WebAuthn Negatives'!J2:J10,"FAIL")),"")
A28: Metrics Events | B28: Open › | C28: 20 | D28: 3 | E28: 7 | F28: 10 | G28: =COUNTIF('Metrics Events'!J2:J21,"PASS") | H28: =COUNTIF('Metrics Events'!J2:J21,"FAIL") | I28: =COUNTIF('Metrics Events'!J2:J21,"BLOCKED") | J28: =20-COUNTIF('Metrics Events'!J2:J21,"PASS")-COUNTIF('Metrics Events'!J2:J21,"FAIL")-COUNTIF('Metrics Events'!J2:J21,"BLOCKED")-COUNTIF('Metrics Events'!J2:J21,"N/A") | K28: =IFERROR(COUNTIF('Metrics Events'!J2:J21,"PASS")/(COUNTIF('Metrics Events'!J2:J21,"PASS")+COUNTIF('Metrics Events'!J2:J21,"FAIL")),"")
A29: NPS Feedback | B29: Open › | C29: 10 | D29: 2 | E29: 3 | F29: 5 | G29: =COUNTIF('NPS Feedback'!J2:J11,"PASS") | H29: =COUNTIF('NPS Feedback'!J2:J11,"FAIL") | I29: =COUNTIF('NPS Feedback'!J2:J11,"BLOCKED") | J29: =10-COUNTIF('NPS Feedback'!J2:J11,"PASS")-COUNTIF('NPS Feedback'!J2:J11,"FAIL")-COUNTIF('NPS Feedback'!J2:J11,"BLOCKED")-COUNTIF('NPS Feedback'!J2:J11,"N/A") | K29: =IFERROR(COUNTIF('NPS Feedback'!J2:J11,"PASS")/(COUNTIF('NPS Feedback'!J2:J11,"PASS")+COUNTIF('NPS Feedback'!J2:J11,"FAIL")),"")
A30: E2E Workflows | B30: Open › | C30: 6 | D30: 3 | E30: 2 | F30: 1 | G30: =COUNTIF('E2E Workflows'!J2:J7,"PASS") | H30: =COUNTIF('E2E Workflows'!J2:J7,"FAIL") | I30: =COUNTIF('E2E Workflows'!J2:J7,"BLOCKED") | J30: =6-COUNTIF('E2E Workflows'!J2:J7,"PASS")-COUNTIF('E2E Workflows'!J2:J7,"FAIL")-COUNTIF('E2E Workflows'!J2:J7,"BLOCKED")-COUNTIF('E2E Workflows'!J2:J7,"N/A") | K30: =IFERROR(COUNTIF('E2E Workflows'!J2:J7,"PASS")/(COUNTIF('E2E Workflows'!J2:J7,"PASS")+COUNTIF('E2E Workflows'!J2:J7,"FAIL")),"")
A31: I18N RTL | B31: Open › | C31: 8 | D31: 0 | E31: 2 | F31: 6 | G31: =COUNTIF('I18N RTL'!J2:J9,"PASS") | H31: =COUNTIF('I18N RTL'!J2:J9,"FAIL") | I31: =COUNTIF('I18N RTL'!J2:J9,"BLOCKED") | J31: =8-COUNTIF('I18N RTL'!J2:J9,"PASS")-COUNTIF('I18N RTL'!J2:J9,"FAIL")-COUNTIF('I18N RTL'!J2:J9,"BLOCKED")-COUNTIF('I18N RTL'!J2:J9,"N/A") | K31: =IFERROR(COUNTIF('I18N RTL'!J2:J9,"PASS")/(COUNTIF('I18N RTL'!J2:J9,"PASS")+COUNTIF('I18N RTL'!J2:J9,"FAIL")),"")
A32: Performance | B32: Open › | C32: 10 | D32: 4 | E32: 5 | F32: 1 | G32: =COUNTIF('Performance'!J2:J11,"PASS") | H32: =COUNTIF('Performance'!J2:J11,"FAIL") | I32: =COUNTIF('Performance'!J2:J11,"BLOCKED") | J32: =10-COUNTIF('Performance'!J2:J11,"PASS")-COUNTIF('Performance'!J2:J11,"FAIL")-COUNTIF('Performance'!J2:J11,"BLOCKED")-COUNTIF('Performance'!J2:J11,"N/A") | K32: =IFERROR(COUNTIF('Performance'!J2:J11,"PASS")/(COUNTIF('Performance'!J2:J11,"PASS")+COUNTIF('Performance'!J2:J11,"FAIL")),"")
A33: Core Edge | B33: Open › | C33: 20 | D33: 9 | E33: 7 | F33: 4 | G33: =COUNTIF('Core Edge'!J2:J21,"PASS") | H33: =COUNTIF('Core Edge'!J2:J21,"FAIL") | I33: =COUNTIF('Core Edge'!J2:J21,"BLOCKED") | J33: =20-COUNTIF('Core Edge'!J2:J21,"PASS")-COUNTIF('Core Edge'!J2:J21,"FAIL")-COUNTIF('Core Edge'!J2:J21,"BLOCKED")-COUNTIF('Core Edge'!J2:J21,"N/A") | K33: =IFERROR(COUNTIF('Core Edge'!J2:J21,"PASS")/(COUNTIF('Core Edge'!J2:J21,"PASS")+COUNTIF('Core Edge'!J2:J21,"FAIL")),"")
A34: GRAND TOTAL | C34: 306 | D34: 122 | E34: 127 | F34: 57 | G34: =SUM(G2:G33) | H34: =SUM(H2:H33) | I34: =SUM(I2:I33) | J34: =SUM(J2:J33) | K34: =IFERROR(G34/(G34+H34),"")

Sheet Authentication
A1: ID | B1: Test Case | C1: Priority | D1: Requirement | E1: Prerequisites | F1: Steps | G1: Test Data | H1: Expected Result | I1: Pass Criteria | J1: Status | K1: Tester | L1: Run Date | M1: Comments / Defect ID
A2: TC-001 | B2: Valid NGO Login | C2: P1 - Critical | D2: FR-AUTH-001 | E2: System is running. Seed data loaded. User fatima@amani.org exists. | F2: 1. Open the application URL (https://web-production-6f8a.up.railway.app) 2. Verify the login page is displayed with email and password fields 3. Enter 'fatima@amani.org' in the Email field 4. Enter 'pass123' in the Password field 5. Click the 'Sign In' button 6. Wait for page to load completely | G2: Email: fatima@amani.org | Password: pass123 | H2: 1. User is redirected to the NGO Dashboard 2. Dashboard displays stat cards: Capacity Score (82%), My Applications, Open Grants, Documents 3. Sidebar shows NGO-specific menu items (Dashboard, Grants, Applications, Assessments, Reports, Documents) 4. Welcome message shows 'Welcome, Fatima' or similar 5. Session cookie is set in browser | I2: Pass: NGO dashboard loads with correct stats. Fail: Login error or wrong dashboard displayed.
A3: TC-002 | B3: Valid Donor Login | C3: P1 - Critical | D3: FR-AUTH-001 | E3: System is running. Seed data loaded. User sarah@globalhealth.org exists. | F3: 1. Open the application URL 2. Enter 'sarah@globalhealth.org' in the Email field 3. Enter 'pass123' in the Password field 4. Click the 'Sign In' button 5. Wait for page to load completely | G3: Email: sarah@globalhealth.org | Password: pass123 | H3: 1. User is redirected to the Donor Dashboard 2. Dashboard displays stat cards: Total Grants, Applications, Pending Reviews, Funding Awarded, Reports Due 3. Sidebar shows Donor-specific menu items (Dashboard, My Grants, Applications, Organizations, Reports, Compliance) 4. Quick action buttons for creating grants, reviewing applications, etc. are visible | I3: Pass: Donor dashboard loads with correct stats and menu. Fail: Login error or wrong role dashboard.
A4: TC-003 | B4: Valid Reviewer Login | C4: P1 - Critical | D4: FR-AUTH-001 | E4: System is running. User james@reviewer.org exists. | F4: 1. Open the application URL 2. Enter 'james@reviewer.org' in the Email field 3. Enter 'pass123' in the Password field 4. Click the 'Sign In' button | G4: Email: james@reviewer.org | Password: pass123 | H4: 1. User is redirected to the Reviewer Dashboard 2. Dashboard displays stat cards: Assigned, In Progress, Completed, Average Score 3. Sidebar shows Reviewer menu items (Dashboard, My Reviews) 4. List of assigned applications is visible | I4: Pass: Reviewer dashboard loads correctly. Fail: Login error or wrong dashboard.
A5: TC-004 | B5: Valid Admin Login | C5: P1 - Critical | D5: FR-AUTH-001 | E5: System is running. User admin@kuja.org exists. | F5: 1. Open the application URL 2. Enter 'admin@kuja.org' in the Email field 3. Enter 'pass123' in the Password field 4. Click the 'Sign In' button | G5: Email: admin@kuja.org | Password: pass123 | H5: 1. User is redirected to the Admin Dashboard 2. Dashboard displays: Users by role breakdown, Organizations by type, Total users count, Flagged compliance items 3. Sidebar shows Admin menu items (Dashboard, Users, Organizations, Grants, Compliance, System) | I5: Pass: Admin dashboard loads with system-wide stats. Fail: Login error or restricted dashboard.
A6: TC-005 | B6: Invalid Credentials - Wrong Password | C6: P1 - Critical | D6: FR-AUTH-002 | E6: System is running. User fatima@amani.org exists. | F6: 1. Open the application URL 2. Enter 'fatima@amani.org' in the Email field 3. Enter 'wrongpassword' in the Password field 4. Click the 'Sign In' button | G6: Email: fatima@amani.org | Password: wrongpassword | H6: 1. Login fails 2. Error message displayed: 'Invalid email or password' 3. User remains on the login page 4. Password field is cleared 5. No session cookie is set | I6: Pass: Error message shown, no redirect. Fail: User logs in or no error message.
A7: TC-006 | B7: Empty Email Field | C7: P2 - High | D7: FR-AUTH-003 | E7: System is running. | F7: 1. Open the application URL 2. Leave the Email field empty 3. Enter 'pass123' in the Password field 4. Click the 'Sign In' button | G7: Email: (empty) | Password: pass123 | H7: 1. Login fails 2. Error message displayed: 'Email and password are required' 3. User remains on the login page | I7: Pass: Validation error shown. Fail: Request sent without email.
A8: TC-007 | B8: Empty Password Field | C8: P2 - High | D8: FR-AUTH-003 | E8: System is running. | F8: 1. Open the application URL 2. Enter 'fatima@amani.org' in the Email field 3. Leave the Password field empty 4. Click the 'Sign In' button | G8: Email: fatima@amani.org | Password: (empty) | H8: 1. Login fails 2. Error message displayed: 'Email and password are required' 3. User remains on the login page | I8: Pass: Validation error shown. Fail: Request sent without password.
A9: TC-008 | B9: Rate Limiting - 5 Failed Attempts | C9: P1 - Critical | D9: FR-AUTH-004 | E9: System is running. No prior failed attempts for the test email. | F9: 1. Open the application URL 2. Enter 'fatima@amani.org' in the Email field 3. Enter 'wrong1' in the Password field and click Sign In 4. Repeat with passwords 'wrong2', 'wrong3', 'wrong4', 'wrong5' 5. On the 6th attempt, enter the correct password 'pass123' 6. Click Sign In | G9: Email: fatima@amani.org | Passwords: wrong1 through wrong5, then pass123 | H9: 1. First 4 attempts show 'Invalid email or password' 2. After 5th failed attempt, message changes to account lockout with remaining time 3. 6th attempt (even with correct password) is rejected with lockout message 4. Message includes countdown or remaining lockout duration | I9: Pass: Account locks after 5 failures, correct password rejected during lockout. Fail: No rate limiting or lockout bypassed.
A10: TC-009 | B10: Rate Limiting Recovery | C10: P2 - High | D10: FR-AUTH-004 | E10: Account has been locked from TC-008. | F10: 1. Wait for the lockout period to expire (typically 5-15 minutes) 2. Enter 'fatima@amani.org' in the Email field 3. Enter 'pass123' in the Password field 4. Click Sign In | G10: Email: fatima@amani.org | Password: pass123 | H10: 1. Login succeeds after lockout period expires 2. User is redirected to NGO Dashboard 3. Failed attempt counter is reset | I10: Pass: Login succeeds after cooldown. Fail: Account remains locked indefinitely.
A11: TC-010 | B11: Session Persistence - Close and Reopen Tab | C11: P2 - High | D11: FR-AUTH-005 | E11: None. | F11: 1. Login as fatima@amani.org / pass123 2. Verify NGO dashboard is displayed 3. Close the browser tab (not the entire browser) 4. Open a new tab and navigate to the application URL 5. Observe the page | G11: Email: fatima@amani.org | Password: pass123 | H11: 1. After reopening, user is still logged in 2. NGO dashboard is displayed without needing to re-login 3. Session cookie persists across tabs | I11: Pass: Session persists across tab close/reopen. Fail: User redirected to login.
A12: TC-011 | B12: Logout | C12: P1 - Critical | D12: FR-AUTH-006 | E12: User is logged in as fatima@amani.org. | F12: 1. Login as fatima@amani.org / pass123 2. Verify NGO dashboard is displayed 3. Click the Logout button (typically in sidebar or user menu) 4. Observe the redirect | G12: Email: fatima@amani.org | Password: pass123 | H12: 1. User is redirected to the login page 2. Session cookie is cleared 3. Navigating back to a protected route shows login page, not cached dashboard | I12: Pass: Session ended, login page shown. Fail: Session persists after logout.
A13: TC-012 | B13: Access Protected Route Without Login | C13: P1 - Critical | D13: FR-AUTH-007 | E13: User is NOT logged in (clear cookies/incognito). | F13: 1. Open an incognito/private browser window 2. Navigate directly to a protected API endpoint: GET /api/auth/me 3. Observe the response | G13: URL: /api/auth/me (no session cookie) | H13: 1. Response status code is 401 Unauthorized 2. Response body contains error message 3. No user data is returned | I13: Pass: 401 returned. Fail: User data returned without authentication.
... A16: TC-015 | B16: Invalid Language Preference via API | C16: P3 - Low | D16: FR-AUTH-008 | E16: User is logged in. | F16: 1. Login as fatima@amani.org / pass123 2. Using browser DevTools or curl, send: PUT /api/auth/language Body: {"language": "xx"} 3. Observe the response | G16: API: PUT /api/auth/language | Body: {"language": "xx"} | H16: 1. Response status code is 400 Bad Request 2. Error message indicates invalid language code 3. Language preference is not changed | I16: Pass: 400 error returned. Fail: Invalid language accepted.

Sheet Dashboard
A1: ID | B1: Test Case | C1: Priority | D1: Requirement | E1: Prerequisites | F1: Steps | G1: Test Data | H1: Expected Result | I1: Pass Criteria | J1: Status | K1: Tester | L1: Run Date | M1: Comments / Defect ID
A2: TC-020 | B2: NGO Dashboard - Stats Cards Display | C2: P1 - Critical | D2: FR-DASH-001 | E2: Logged in as fatima@amani.org. Seed data loaded. | F2: 1. Login as fatima@amani.org / pass123 2. Verify the NGO Dashboard loads 3. Observe the stat cards at the top of the dashboard 4. Note the values displayed in each card | G2: Email: fatima@amani.org | Password: pass123 | H2: 1. Dashboard displays 4 stat cards: - Capacity Score: 82% - My Applications: count of applications - Open Grants: count of available grants - Documents: count of uploaded documents 2. Each card has an icon, label, and numeric value 3. Quick action buttons are visible below stats | I2: Pass: All 4 stat cards display with correct data. Fail: Missing cards or incorrect values.
A3: TC-021 | B3: Donor Dashboard - Stats Cards Display | C3: P1 - Critical | D3: FR-DASH-002 | E3: Logged in as sarah@globalhealth.org. Seed data loaded. | F3: 1. Login as sarah@globalhealth.org / pass123 2. Verify the Donor Dashboard loads 3. Observe the stat cards 4. Note the values in each card | G3: Email: sarah@globalhealth.org | Password: pass123 | H3: 1. Dashboard displays stat cards: - Total Grants: count of donor's grants - Applications: count of received applications - Pending Reviews: applications awaiting review - Funding Awarded: total amount awarded - Reports Due: pending report reviews 2. Grant status breakdown visible 3. Quick actions: Create Grant, Review Applications, etc. | I3: Pass: Donor stats display correctly. Fail: Missing or incorrect metrics.
A4: TC-022 | B4: Reviewer Dashboard - Stats Cards Display | C4: P1 - Critical | D4: FR-DASH-003 | E4: Logged in as james@reviewer.org. | F4: 1. Login as james@reviewer.org / pass123 2. Verify the Reviewer Dashboard loads 3. Observe the stat cards | G4: Email: james@reviewer.org | Password: pass123 | H4: 1. Dashboard displays stat cards: - Assigned: number of assigned reviews - In Progress: reviews currently being worked on - Completed: finished reviews - Average Score: mean of all review scores 2. List of assigned applications visible | I4: Pass: Reviewer stats shown correctly. Fail: Missing cards or no review list.
A5: TC-023 | B5: Admin Dashboard - System Stats Display | C5: P1 - Critical | D5: FR-DASH-004 | E5: Logged in as admin@kuja.org. | F5: 1. Login as admin@kuja.org / pass123 2. Verify the Admin Dashboard loads 3. Observe system-wide statistics | G5: Email: admin@kuja.org | Password: pass123 | H5: 1. Dashboard displays system stats: - Users by role (NGO, Donor, Reviewer, Admin counts) - Organizations by type - Total users count - Flagged compliance items 2. Admin-specific menu items visible in sidebar | I5: Pass: Admin stats with role breakdown visible. Fail: Missing system stats.
A6: TC-024 | B6: NGO Dashboard - Data Accuracy Verification | C6: P2 - High | D6: FR-DASH-005 | E6: Logged in as fatima@amani.org. Known seed data: 2 submitted applications for Amani. | F6: 1. Login as fatima@amani.org / pass123 2. Note the 'My Applications' count on dashboard 3. Navigate to 'Applications' page from sidebar 4. Count the actual applications listed 5. Return to dashboard and compare | G6: Email: fatima@amani.org | Password: pass123 | H6: 1. Dashboard 'My Applications' count matches actual number of applications in the list 2. 'Open Grants' count matches the number of grants with 'open' status 3. 'Documents' count matches uploaded documents count 4. Capacity Score matches the assessment score from the profile | I6: Pass: All dashboard numbers match actual data. Fail: Any count mismatch.
A7: TC-025 | B7: NGO Dashboard - Quick Actions Navigation | C7: P2 - High | D7: FR-DASH-006 | E7: Logged in as fatima@amani.org. | F7: 1. Login as fatima@amani.org / pass123 2. On the dashboard, locate the quick action buttons 3. Click 'Browse Grants' quick action 4. Verify navigation to Grants page 5. Return to dashboard 6. Click 'My Applications' quick action 7. Verify navigation to Applications page 8. Repeat for each available quick action | G7: Email: fatima@amani.org | Password: pass123 | H7: 1. Each quick action button navigates to the correct page 2. Back navigation returns to dashboard 3. No broken links or error pages | I7: Pass: All quick actions navigate correctly. Fail: Broken link or wrong page.
A8: TC-026 | B8: Donor Dashboard - Quick Actions Navigation | C8: P2 - High | D8: FR-DASH-006 | E8: Logged in as sarah@globalhealth.org. | F8: 1. Login as sarah@globalhealth.org / pass123 2. On the donor dashboard, locate quick actions 3. Click 'Create Grant' quick action 4. Verify grant creation wizard opens 5. Return to dashboard 6. Click 'Review Applications' quick action 7. Verify applications list opens | G8: Email: sarah@globalhealth.org | Password: pass123 | H8: 1. 'Create Grant' opens the grant creation wizard 2. 'Review Applications' shows applications for donor's grants 3. Each quick action navigates to the correct page | I8: Pass: All donor quick actions work correctly. Fail: Navigation errors.
A9: TC-027 | B9: Dashboard Responsive Layout | C9: P3 - Low | D9: FR-DASH-007 | E9: Logged in as any user. | F9: 1. Login as fatima@amani.org / pass123 2. View dashboard at full desktop width (1920px) 3. Resize browser to tablet width (~768px) 4. Resize to mobile width (~375px) 5. Observe stat cards and layout at each breakpoint | G9: Email: fatima@amani.org | Password: pass123 | H9: 1. Desktop: stat cards in a horizontal row, sidebar visible 2. Tablet: stat cards may wrap to 2 columns, sidebar may collapse 3. Mobile: stat cards stack vertically, sidebar is hamburger menu 4. No horizontal scrollbar at any width 5. All text remains readable | I9: Pass: Layout adapts correctly at all breakpoints. Fail: Overflow or unreadable content.
A10: TC-028 | B10: Dashboard Auto-Refresh on Navigation | C10: P3 - Low | D10: FR-DASH-008 | E10: Logged in as fatima@amani.org. | F10: 1. Login as fatima@amani.org / pass123 2. Note dashboard stats 3. Navigate to another section (e.g., Grants) 4. Navigate back to Dashboard 5. Verify stats are refreshed (not stale cached data) | G10: Email: fatima@amani.org | Password: pass123 | H10: 1. Dashboard stats refresh when returning to dashboard page 2. API call is made to fetch fresh data 3. Stats reflect any changes made during the session | I10: Pass: Dashboard data refreshes on navigation. Fail: Stale data displayed.

Sheet Grants
A1: ID | B1: Test Case | C1: Priority | D1: Requirement | E1: Prerequisites | F1: Steps | G1: Test Data | H1: Expected Result | I1: Pass Criteria | J1: Status | K1: Tester | L1: Run Date | M1: Comments / Defect ID
A2: TC-030 | B2: Browse Open Grants (NGO) | C2: P1 - Critical | D2: FR-GRNT-001 | E2: Logged in as NGO user. Open grants exist in system. | F2: 1. Login as fatima@amani.org / pass123 2. Click 'Grants' in the sidebar menu 3. Observe the grants list page | G2: Email: fatima@amani.org | Password: pass123 | H2: 1. Grants page displays list of open grants 2. Each grant card shows: Title, Funding Amount, Deadline, Sectors, Countries 3. At least 3 open grants visible (Community Health Workers, Education Technology, Women's Protection) 4. Draft grants (Climate Resilience) are NOT visible to NGOs 5. 'Apply' button visible on eligible grants | I2: Pass: Open grants listed with correct details, drafts hidden. Fail: Missing grants or drafts shown.
A3: TC-031 | B3: Grant Search Filter | C3: P2 - High | D3: FR-GRNT-002 | E3: Logged in as NGO user. Multiple grants exist. | F3: 1. Login as fatima@amani.org / pass123 2. Navigate to Grants page 3. Locate the search/filter input 4. Type 'Health' in the search box 5. Observe the filtered results 6. Clear search and type 'Education' 7. Observe filtered results | G3: Search terms: 'Health', 'Education' | H3: 1. Searching 'Health' shows: 'Community Health Workers Scale-Up Program' 2. 'Education Technology' grant is filtered out when searching 'Health' 3. Searching 'Education' shows: 'Education Technology for Rural Schools' 4. Filter is case-insensitive 5. Results update in real-time as user types | I3: Pass: Search filters grants correctly. Fail: Wrong results or no filtering.
A4: TC-032 | B4: Grant Detail View | C4: P1 - Critical | D4: FR-GRNT-003 | E4: Logged in as NGO user. 'Community Health Workers' grant exists. | F4: 1. Login as fatima@amani.org / pass123 2. Navigate to Grants page 3. Click on 'Community Health Workers Scale-Up Program' 4. Review all sections on the detail page | G4: Email: fatima@amani.org | Grant: Community Health Workers Scale-Up Program | H4: 1. Grant detail page displays: - Title: Community Health Workers Scale-Up Program - Funding: $500,000 - Donor: Global Health Fund - Countries: Kenya, Somalia, Uganda - Status: Open 2. Eligibility section with requirements 3. Evaluation criteria section with weights 4. Required documents list 5. Apply button visible at the bottom | I4: Pass: All grant details shown correctly. Fail: Missing sections or wrong data.
A5: TC-033 | B5: Create Grant - Step 1 Basic Info (Donor) | C5: P1 - Critical | D5: FR-GRNT-004 | E5: Logged in as sarah@globalhealth.org (Donor). | F5: 1. Login as sarah@globalhealth.org / pass123 2. Click 'Create Grant' button on dashboard or sidebar 3. In Step 1 (Basic Information), fill in: - Title: 'Water Security in Horn of Africa' - Description: 'Program to improve water access in drought-affected regions' - Funding Amount: 750000 - Application Deadline: 2026-06-30 - Sectors: WASH, Climate - Countries: Kenya, Somalia, Ethiopia 4. Click 'Next' to proceed to Step 2 | G5: Title: Water Security in Horn of Africa | Amount: $750,000 | Deadline: 2026-06-30 | H5: 1. Grant creation wizard opens at Step 1 2. All fields accept input correctly 3. Multi-select works for sectors and countries 4. Clicking Next advances to Step 2 5. Data is preserved (going back shows entered data) | I5: Pass: Step 1 data captured, advances to Step 2. Fail: Validation errors or data loss.
A6: TC-034 | B6: Create Grant - Step 2 Eligibility | C6: P1 - Critical | D6: FR-GRNT-005 | E6: Continuing from TC-033, on Step 2 of grant creation. | F6: 1. In Step 2 (Eligibility Requirements), add requirements: - 'Registered NGO in target country' (Required: Yes) - 'Minimum 3 years WASH experience' (Required: Yes) - 'Annual budget exceeds $100,000' (Required: No) 2. Click 'Add Requirement' for each 3. Review the list of added requirements 4. Click Next to proceed to Step 3 | G6: 3 eligibility requirements with varying required status | H6: 1. Requirements are added to the list 2. Each shows text and required/optional status 3. Requirements can be reordered or deleted 4. Clicking Next advances to Step 3 | I6: Pass: Requirements saved and visible. Fail: Requirements lost or validation error.
A7: TC-035 | B7: Create Grant - Step 3 Evaluation Criteria | C7: P1 - Critical | D7: FR-GRNT-006 | E7: Continuing from TC-034, on Step 3. | F7: 1. In Step 3 (Evaluation Criteria), add criteria: - 'Technical Approach' - Weight: 30% - 'Organizational Capacity' - Weight: 25% - 'Budget Reasonableness' - Weight: 25% - 'Impact & Sustainability' - Weight: 20% 2. Verify total weight displays 100% 3. Click Next to proceed | G7: 4 criteria: Technical (30%), Capacity (25%), Budget (25%), Impact (20%) | H7: 1. Criteria added with weights 2. Running total shows 100% 3. System accepts the configuration 4. Advances to Step 4 | I7: Pass: Criteria with 100% total weight accepted. Fail: Weight calculation error.
A8: TC-036 | B8: Create Grant - Invalid Criteria Weight Total | C8: P2 - High | D8: FR-GRNT-006 | E8: On Step 3 of grant creation. | F8: 1. Add criteria with weights that do NOT sum to 100%: - 'Technical Approach' - Weight: 40% - 'Capacity' - Weight: 30% (Total: 70%, not 100%) 2. Try to click Next | G8: 2 criteria: Technical (40%), Capacity (30%) = 70% total | H8: 1. Validation error displayed: weights must sum to 100% 2. Cannot proceed to next step 3. Total weight indicator shows 70% with warning | I8: Pass: Validation prevents proceeding. Fail: Allows advancement with non-100% weights.
A9: TC-037 | B9: Create Grant - Step 4 Documents | C9: P1 - Critical | D9: FR-GRNT-007 | E9: Continuing from TC-035, on Step 4. | F9: 1. In Step 4 (Required Documents), select document types: - Financial Report (Required) - Registration Certificate (Required) - Audit Report (Required) - PSEA Policy (Required) - Strategic Plan (Optional) 2. For each, set AI evaluation criteria if available 3. Click Next to proceed | G9: 5 document types with required/optional flags | H9: 1. Document types selected and displayed 2. Required/optional flags set correctly 3. AI evaluation criteria can be configured per document type 4. Advances to Step 5 | I9: Pass: Document requirements configured. Fail: Configuration lost or error.
A10: TC-038 | B10: Create Grant - Step 5 Reporting Requirements | C10: P1 - Critical | D10: FR-GRNT-008 | E10: Continuing from TC-037, on Step 5. | F10: 1. In Step 5 (Reporting), configure: - Reporting Frequency: Quarterly - Report Types: Financial, Narrative - Add specific requirements for each report type 2. Click Next to proceed to Review | G10: Quarterly reporting with Financial and Narrative types | H10: 1. Reporting configuration saved 2. Report template sections displayed 3. Advances to final Review step | I10: Pass: Reporting requirements configured. Fail: Configuration not saved.
A11: TC-039 | B11: Create Grant - Step 6 Review and Publish | C11: P1 - Critical | D11: FR-GRNT-009 | E11: Continuing from TC-038, on final Review step. | F11: 1. In Step 6 (Review), verify all entered information: - Basic info, eligibility, criteria, documents, reporting 2. Click 'Publish Grant' 3. Wait for confirmation | G11: All data from TC-033 through TC-038 | H11: 1. Review page shows summary of all configuration 2. After publishing, grant status = 'open' 3. Success message displayed 4. Grant appears in the grants list for NGOs 5. Redirected to grant detail page or grants list | I11: Pass: Grant published and visible to NGOs. Fail: Grant not created or not visible.
A12: TC-040 | B12: Create Grant as NGO (Unauthorized) | C12: P1 - Critical | D12: FR-GRNT-010 | E12: Logged in as NGO user. | F12: 1. Login as fatima@amani.org / pass123 2. Using browser DevTools or curl, send: POST /api/grants/ Body: {"title": "Test Grant", "description": "Test", "amount": 100000} 3. Observe the response | G12: Email: fatima@amani.org | API: POST /api/grants/ | H12: 1. Response status code is 403 Forbidden 2. Error message: 'Donor role required' or similar 3. No grant is created in the system | I12: Pass: 403 returned, no grant created. Fail: Grant created by NGO user.
A13: TC-041 | B13: Grant Agreement Upload with AI Extraction | C13: P1 - Critical | D13: FR-GRNT-011 | E13: Logged in as donor, in grant creation wizard. | F13: 1. Login as sarah@globalhealth.org / pass123 2. Start creating a new grant 3. In the grant agreement section, click 'Upload Grant Agreement' 4. Select the file 'grant_agreement_sample.txt' from test-files/ 5. Wait for AI analysis to complete 6. Review extracted requirements | G13: File: test-files/grant_agreement_sample.txt | H13: 1. File uploads successfully 2. Loading indicator shown during AI analysis 3. AI extracts reporting requirements: - Report types (financial, narrative, impact) - Frequencies (quarterly, annual) - Specific deadlines or due dates 4. Extracted requirements displayed for donor review 5. Donor can modify or add to extracted requirements | I13: Pass: AI extracts meaningful requirements from agreement. Fail: Extraction fails or returns empty.
... A17: TC-045 | B17: Grant Country Filter | C17: P2 - High | D17: FR-GRNT-002 | E17: Logged in as NGO user. | F17: 1. Login as fatima@amani.org / pass123 2. Navigate to Grants page 3. Use country filter to select 'Kenya' 4. Observe filtered results 5. Change filter to 'Nigeria' 6. Observe updated results | G17: Country filters: Kenya, Nigeria | H17: 1. 'Kenya' filter shows grants targeting Kenya (Community Health Workers, Education Technology) 2. 'Nigeria' filter shows Women's Protection grant 3. Filter updates dynamically | I17: Pass: Country filter works correctly. Fail: Wrong grants shown.

Sheet Applications
A1: ID | B1: Test Case | C1: Priority | D1: Requirement | E1: Prerequisites | F1: Steps | G1: Test Data | H1: Expected Result | I1: Pass Criteria | J1: Status | K1: Tester | L1: Run Date | M1: Comments / Defect ID
A2: TC-060 | B2: Start New Application | C2: P1 - Critical | D2: FR-APPL-001 | E2: Logged in as fatima@amani.org. 'Education Technology' grant is open and Amani has not applied. | F2: 1. Login as fatima@amani.org / pass123 2. Navigate to Grants page 3. Find 'Education Technology for Rural Schools' 4. Click 'Apply' button 5. Observe the application wizard | G2: Email: fatima@amani.org | Grant: Education Technology for Rural Schools | H2: 1. Application wizard opens at Step 1 (Eligibility) 2. Grant name displayed in wizard header 3. Eligibility checklist items shown 4. Step progress indicator shows Step 1 of 4 | I2: Pass: Application wizard opens at Step 1. Fail: Error or wrong page.
A3: TC-061 | B3: Eligibility Check - All Requirements Met | C3: P1 - Critical | D3: FR-APPL-002 | E3: In Step 1 of application wizard from TC-060. | F3: 1. Check all eligibility requirement checkboxes 2. Observe the status indicators 3. Click 'Next' to proceed to Step 2 | G3: All eligibility items checked | H3: 1. All items show green checkmarks 2. 'Next' button becomes enabled 3. Proceeds to Step 2 (Proposal Responses) | I3: Pass: All items checked, advances to Step 2. Fail: Cannot proceed.
A4: TC-062 | B4: Eligibility Check - Required Item Unchecked | C4: P2 - High | D4: FR-APPL-002 | E4: In Step 1 of application wizard. | F4: 1. Check most eligibility items but leave one REQUIRED item unchecked 2. Try to click 'Next' | G4: One required eligibility item left unchecked | H4: 1. Warning message displayed about unmet requirement 2. Cannot proceed to Step 2 3. The unchecked required item is highlighted | I4: Pass: Warning shown, cannot proceed. Fail: Proceeds with unmet requirements.
A5: TC-063 | B5: Proposal Response with AI Guidance | C5: P1 - Critical | D5: FR-APPL-003 | E5: In Step 2 of application wizard. | F5: 1. In Step 2 (Proposal), find the first criterion text area 2. Click the 'AI Guidance' button next to it 3. Wait for AI to generate guidance 4. Read the guidance provided 5. Write a response in the text area based on the guidance | G5: Criterion: first evaluation criterion for the grant | H5: 1. AI Guidance button triggers API call 2. Loading indicator shown while AI processes 3. AI returns relevant writing suggestions 4. Suggestions appear in a panel/tooltip near the text area 5. Suggestions are in the user's selected language | I5: Pass: AI guidance generated and relevant. Fail: No guidance or irrelevant suggestions.
A6: TC-064 | B6: Proposal Response Word Count | C6: P2 - High | D6: FR-APPL-004 | E6: In Step 2 of application wizard. | F6: 1. In a criterion response text area, type a very long response 2. Continue typing past any word count limit 3. Observe the word count indicator | G6: Long text exceeding typical 500-word limit | H6: 1. Word count indicator shows current/max words 2. When exceeding limit, indicator turns red/warning 3. Warning message about exceeding word limit | I6: Pass: Word count tracking works with warning. Fail: No word count or no warning.
A7: TC-065 | B7: Document Upload - Valid PDF | C7: P1 - Critical | D7: FR-APPL-005 | E7: In Step 3 of application wizard. test-files-v3/valid_financial_report.pdf available. | F7: 1. In Step 3 (Documents), find 'Financial Report' upload area 2. Click 'Upload' or drag the file valid_financial_report.pdf 3. Wait for upload and AI analysis to complete 4. Review the AI analysis results | G7: File: test-files-v3/valid_financial_report.pdf | H7: 1. File uploads successfully (progress bar shown) 2. AI analysis runs automatically after upload 3. AI score displayed (expected: 70-90) 4. Analysis findings listed 5. Document appears in the uploaded documents list with green status | I7: Pass: File uploaded, AI score shown. Fail: Upload fails or no AI analysis.
A8: TC-066 | B8: Document Upload - Invalid File Type (EXE) | C8: P1 - Critical | D8: FR-APPL-006 | E8: In Step 3 of application wizard. | F8: 1. In Step 3, attempt to upload 'malicious_script.html' 2. Observe the system response | G8: File: test-files-v3/malicious_script.html | H8: 1. File is rejected before upload 2. Error message: 'File type not allowed' or similar 3. No file is stored on the server 4. Only PDF, DOC, DOCX, XLS, XLSX, TXT, CSV formats accepted | I8: Pass: File rejected with error. Fail: File accepted.
A9: TC-067 | B9: Document Upload - Oversized File | C9: P2 - High | D9: FR-APPL-006 | E9: In Step 3 of application wizard. A file >16MB available. | F9: 1. Create or use a PDF file larger than 16MB 2. Attempt to upload it in Step 3 3. Observe the system response | G9: File: large file > 16MB (or 10MB per system config) | H9: 1. File is rejected with size error 2. Error message: 'File too large. Max 10 MB' or 'Max 16 MB' 3. No file is stored | I9: Pass: File rejected with size error. Fail: Large file accepted.
A10: TC-068 | B10: Document Upload - Empty/Corrupt PDF | C10: P2 - High | D10: FR-APPL-007 | E10: In Step 3 of application wizard. | F10: 1. Upload the file 'invalid_empty.pdf' (minimal PDF structure, no content) 2. Wait for upload and AI analysis 3. Review the analysis results | G10: File: test-files-v3/invalid_empty.pdf | H10: 1. File uploads (valid PDF structure) 2. AI analysis returns very low score (5-15) 3. Analysis notes: 'Document appears empty' or 'No meaningful content' 4. Warning indicator shown | I10: Pass: Low AI score with appropriate warning. Fail: High score for empty document.
A11: TC-069 | B11: Application Review Step - Summary | C11: P1 - Critical | D11: FR-APPL-008 | E11: Steps 1-3 completed in application wizard. | F11: 1. Navigate to Step 4 (Review & Submit) 2. Review the summary of all entered information 3. Check completion indicators for each section | G11: All previous steps completed | H11: 1. Summary shows: - Eligibility: all items checked - Proposal: responses for each criterion with word counts - Documents: uploaded files with AI scores 2. Completion indicators show green for completed sections 3. 'Submit Application' button is visible | I11: Pass: Complete summary displayed. Fail: Missing sections or wrong data.
A12: TC-070 | B12: Submit Application | C12: P1 - Critical | D12: FR-APPL-009 | E12: In Step 4 of application wizard, all sections complete. | F12: 1. On the Review step, verify all sections are complete 2. Click 'Submit Application' 3. Wait for processing 4. Observe the confirmation | G12: Complete application ready for submission | H12: 1. Application submitted successfully 2. Status changes from 'draft' to 'submitted' 3. AI calculates overall application score 4. Confirmation message displayed with score 5. Application appears in 'My Applications' list with 'Submitted' status 6. Timestamp recorded for submission | I12: Pass: Status = submitted, score calculated. Fail: Error on submission.
A13: TC-071 | B13: Duplicate Application Prevention | C13: P1 - Critical | D13: FR-APPL-010 | E13: fatima@amani.org has already submitted application for 'Community Health Workers'. | F13: 1. Login as fatima@amani.org / pass123 2. Navigate to Grants page 3. Find 'Community Health Workers Scale-Up Program' 4. Try to click 'Apply' again 5. Alternatively, via API: POST /api/applications/ with grant_id=1 | G13: Email: fatima@amani.org | Grant: Community Health Workers (already applied) | H13: 1. Apply button is disabled or hidden (already applied) 2. If API call made: 409 Conflict 3. Message: 'Already applied to this grant' or 'Application exists' 4. No duplicate application created | I13: Pass: Duplicate prevented (409 or disabled button). Fail: Duplicate application created.
... A23: TC-081 | B23: View Applicant Rankings (Donor) | C23: P1 - Critical | D23: FR-APPL-020 | E23: Logged in as sarah@globalhealth.org. Multiple applications with scores. | F23: 1. Login as sarah@globalhealth.org / pass123 2. Navigate to 'Community Health Workers' grant 3. View applications/rankings 4. Check the ordering | G23: Email: sarah@globalhealth.org | Grant: Community Health Workers | H23: 1. Applications listed in descending score order 2. Amani (78.5) ranked above Salam Relief (62.3) 3. Each entry shows: NGO name, score, status, review status 4. Award/reject action buttons available | I23: Pass: Ranked list in descending order. Fail: Wrong order or missing scores.

Sheet Assessments
A1: ID | B1: Test Case | C1: Priority | D1: Requirement | E1: Prerequisites | F1: Steps | G1: Test Data | H1: Expected Result | I1: Pass Criteria | J1: Status | K1: Tester | L1: Run Date | M1: Comments / Defect ID
A2: TC-090 | B2: Start Kuja Framework Assessment | C2: P1 - Critical | D2: FR-ASMT-001 | E2: Logged in as fatima@amani.org. | F2: 1. Login as fatima@amani.org / pass123 2. Click 'Assessments' in the sidebar 3. Click 'Start New Assessment' 4. Select 'Kuja Standard' framework 5. Observe the checklist displayed | G2: Email: fatima@amani.org | Framework: Kuja Standard | H2: 1. Kuja assessment checklist displayed 2. 5 categories visible with total of 26 items 3. Categories: Governance, Financial, Technical, HR, Compliance (or equivalent) 4. Each item has a checkbox and description 5. Score starts at 0% | I2: Pass: Kuja checklist with 5 categories displayed. Fail: Wrong framework or missing items.
A3: TC-091 | B3: Complete Kuja Checklist | C3: P1 - Critical | D3: FR-ASMT-002 | E3: Kuja assessment started from TC-090. | F3: 1. Check various items across all 5 categories 2. For each category, check approximately 70-80% of items 3. Observe the score calculations updating 4. Click 'Complete Assessment' | G3: Approximately 70-80% of items checked across all categories | H3: 1. Category scores calculate as (checked/total) x 100 x weight 2. Overall score is sum of weighted category scores 3. Score updates in real-time as items are checked/unchecked 4. Assessment saved on completion 5. Results page shows score, category breakdown, gaps | I3: Pass: Correct score calculation and saved. Fail: Wrong score or save failure.
A4: TC-092 | B4: Start STEP Framework Assessment | C4: P2 - High | D4: FR-ASMT-001 | E4: Logged in as NGO user. | F4: 1. Login as ahmed@salamrelief.org / pass123 2. Navigate to Assessments 3. Start new assessment 4. Select 'STEP' framework 5. Verify checklist content | G4: Email: ahmed@salamrelief.org | Framework: STEP | H4: 1. STEP checklist displayed with 5 categories 2. Items relevant to STEP framework 3. Different from Kuja items | I4: Pass: STEP checklist displayed correctly. Fail: Wrong framework items.
A5: TC-093 | B5: Start UN-HACT Framework Assessment | C5: P2 - High | D5: FR-ASMT-001 | E5: Logged in as NGO user. | F5: 1. Login as thandi@ubuntu.org / pass123 2. Navigate to Assessments 3. Start new assessment, select 'UN-HACT' 4. Verify checklist | G5: Email: thandi@ubuntu.org | Framework: UN-HACT | H5: 1. UN-HACT checklist with 5 categories, 22 items 2. Items reflect UN-HACT micro-assessment criteria | I5: Pass: UN-HACT checklist correct. Fail: Wrong items or count.
A6: TC-094 | B6: Start CHS Framework Assessment | C6: P2 - High | D6: FR-ASMT-001 | E6: Logged in as NGO user. | F6: 1. Login as aisha@sahelwomen.org / pass123 2. Navigate to Assessments 3. Start new assessment, select 'CHS' 4. Verify checklist | G6: Email: aisha@sahelwomen.org | Framework: CHS | H6: 1. CHS checklist with 7 categories, 27 items 2. Items aligned to Core Humanitarian Standard commitments | I6: Pass: CHS checklist with 7 categories. Fail: Wrong structure.
A7: TC-095 | B7: Start NUPAS Framework Assessment | C7: P2 - High | D7: FR-ASMT-001 | E7: Logged in as NGO user. | F7: 1. Login as peter@hopebridges.org / pass123 2. Navigate to Assessments 3. Start new assessment, select 'NUPAS' 4. Verify checklist | G7: Email: peter@hopebridges.org | Framework: NUPAS | H7: 1. NUPAS checklist with 5 categories, 26 items 2. Items reflect NUPAS assessment criteria | I7: Pass: NUPAS checklist correct. Fail: Wrong items.
A8: TC-096 | B8: Assessment Score Calculation Accuracy | C8: P1 - Critical | D8: FR-ASMT-003 | E8: In Kuja assessment with known items. | F8: 1. Start Kuja assessment 2. In Category 1 (e.g., 5 items, weight 25%), check 4 out of 5 3. In Category 2 (e.g., 6 items, weight 20%), check 3 out of 6 4. Leave other categories at 0 5. Calculate expected score manually 6. Compare with displayed score | G8: Category 1: 4/5 checked (80%), Category 2: 3/6 checked (50%) | H8: 1. Category 1 score = (4/5) x 100 x 0.25 = 20.0 2. Category 2 score = (3/6) x 100 x 0.20 = 10.0 3. Overall = 20.0 + 10.0 = 30.0% 4. Displayed score matches manual calculation | I8: Pass: Score matches manual calculation. Fail: Score mismatch.
A9: TC-097 | B9: Assessment Gaps Identification | C9: P2 - High | D9: FR-ASMT-004 | E9: Assessment completed with some items unchecked. | F9: 1. Complete an assessment with some items unchecked 2. Click 'Complete Assessment' 3. View the results page 4. Look for the 'Gaps' or 'Recommendations' section | G9: Assessment with gaps in multiple categories | H9: 1. Unchecked items listed as capacity gaps 2. Gaps organized by category 3. Recommendations provided for addressing gaps 4. Priority indicators for critical gaps | I9: Pass: Gaps correctly identified. Fail: Missing gaps or wrong items listed.
A10: TC-098 | B10: Assessment Document Upload | C10: P2 - High | D10: FR-ASMT-005 | E10: In assessment wizard. | F10: 1. During assessment, find the document upload area 2. Upload a supporting document (e.g., valid_audit_report.pdf) 3. Wait for upload to complete | G10: File: test-files-v3/valid_audit_report.pdf | H10: 1. Document uploaded successfully 2. Document linked to the assessment 3. File name displayed in the uploaded list | I10: Pass: Document uploaded and linked. Fail: Upload fails.
A11: TC-099 | B11: View Assessment Results | C11: P1 - Critical | D11: FR-ASMT-006 | E11: Assessment completed. | F11: 1. After completing assessment, view results page 2. Review all sections of the results | G11: Completed assessment | H11: 1. Results page shows: - Overall score (percentage) - Category-by-category breakdown with scores - Visual indicators (progress bars or charts) - List of gaps (unchecked items) - Recommendations for improvement | I11: Pass: Comprehensive results displayed. Fail: Missing sections.
A12: TC-100 | B12: Assessment Updates Organization Profile | C12: P1 - Critical | D12: FR-ASMT-007 | E12: Assessment completed for an NGO. | F12: 1. Complete a new assessment 2. Navigate to the organization profile 3. Verify the assessment score and date are updated | G12: Newly completed assessment | H12: 1. Organization profile shows updated assess_score 2. assess_date reflects the completion date 3. Score visible to donors searching organizations | I12: Pass: Profile updated with new score/date. Fail: Old score persists.

Sheet AI Services
A1: ID | B1: Test Case | C1: Priority | D1: Requirement | E1: Prerequisites | F1: Steps | G1: Test Data | H1: Expected Result | I1: Pass Criteria | J1: Status | K1: Tester | L1: Run Date | M1: Comments / Defect ID
A2: TC-120 | B2: AI Chat - Basic Question | C2: P1 - Critical | D2: FR-AI-001 | E2: Logged in as any user. ANTHROPIC_API_KEY configured. | F2: 1. Login as fatima@amani.org / pass123 2. Open the AI Chat panel (typically a button/icon in the header or sidebar) 3. Type: 'What can Kuja help with?' 4. Press Enter or click Send 5. Wait for AI response | G2: Question: 'What can Kuja help with?' | H2: 1. AI panel opens 2. Loading indicator while processing 3. AI responds with relevant platform information 4. Response is contextual and accurate about Kuja features 5. Response appears within reasonable time (< 15 seconds) | I2: Pass: AI responds with relevant info. Fail: Error, timeout, or irrelevant response.
A3: TC-121 | B3: AI Chat - Role-Specific Guidance | C3: P2 - High | D3: FR-AI-002 | E3: Logged in as NGO user. | F3: 1. Login as fatima@amani.org / pass123 2. Open AI Chat 3. Ask: 'How do I strengthen my application?' 4. Review the response | G3: Question: 'How do I strengthen my application?' | H3: 1. AI provides NGO-specific advice 2. Response references proposal writing, document quality, capacity scores 3. Advice is actionable and relevant to the NGO context 4. Does not provide donor-specific or admin-specific guidance | I3: Pass: Role-appropriate advice given. Fail: Generic or wrong-role advice.
A4: TC-122 | B4: AI Chat in French | C4: P2 - High | D4: FR-AI-003 | E4: Logged in. Language set to French. | F4: 1. Login as fatima@amani.org / pass123 2. Switch language to French 3. Open AI Chat 4. Ask: 'Comment renforcer ma candidature?' 5. Review the response | G4: Language: French | Question: 'Comment renforcer ma candidature?' | H4: 1. AI responds entirely in French 2. Response is grammatically correct French 3. Content is relevant and helpful 4. No English text mixed in | I4: Pass: Complete French response. Fail: English or mixed-language response.
